Traceback (most recent call last):
  File "/Users/mhjensen/miniforge3/envs/myenv/lib/python3.9/site-packages/jupyter_cache/executors/utils.py", line 51, in single_nb_execution
    executenb(
  File "/Users/mhjensen/miniforge3/envs/myenv/lib/python3.9/site-packages/nbclient/client.py", line 1204, in execute
    return NotebookClient(nb=nb, resources=resources, km=km, **kwargs).execute()
  File "/Users/mhjensen/miniforge3/envs/myenv/lib/python3.9/site-packages/nbclient/util.py", line 84, in wrapped
    return just_run(coro(*args, **kwargs))
  File "/Users/mhjensen/miniforge3/envs/myenv/lib/python3.9/site-packages/nbclient/util.py", line 62, in just_run
    return loop.run_until_complete(coro)
  File "/Users/mhjensen/miniforge3/envs/myenv/lib/python3.9/asyncio/base_events.py", line 647, in run_until_complete
    return future.result()
  File "/Users/mhjensen/miniforge3/envs/myenv/lib/python3.9/site-packages/nbclient/client.py", line 663, in async_execute
    await self.async_execute_cell(
  File "/Users/mhjensen/miniforge3/envs/myenv/lib/python3.9/site-packages/nbclient/client.py", line 965, in async_execute_cell
    await self._check_raise_for_error(cell, cell_index, exec_reply)
  File "/Users/mhjensen/miniforge3/envs/myenv/lib/python3.9/site-packages/nbclient/client.py", line 862, in _check_raise_for_error
    raise CellExecutionError.from_cell_and_msg(cell, exec_reply_content)
nbclient.exceptions.CellExecutionError: An error occurred while executing the following cell:
------------------
new_hobbit = {'First Name': ["Peregrin"],
              'Last Name': ["Took"],
              'Place of birth': ["Shire"],
              'Date of Birth T.A.': [2990]
              }
data_pandas=data_pandas.append(pd.DataFrame(new_hobbit, index=['Pippin']))
display(data_pandas)
------------------

[0;31m---------------------------------------------------------------------------[0m
[0;31mAttributeError[0m                            Traceback (most recent call last)
[0;32m/var/folders/td/3yk470mj5p931p9dtkk0y6jw0000gn/T/ipykernel_77069/1326197715.py[0m in [0;36m?[0;34m()[0m
[0;32m----> 6[0;31m new_hobbit = {'First Name': ["Peregrin"],
[0m[1;32m      7[0m               [0;34m'Last Name'[0m[0;34m:[0m [0;34m[[0m[0;34m"Took"[0m[0;34m][0m[0;34m,[0m[0;34m[0m[0;34m[0m[0m
[1;32m      8[0m               [0;34m'Place of birth'[0m[0;34m:[0m [0;34m[[0m[0;34m"Shire"[0m[0;34m][0m[0;34m,[0m[0;34m[0m[0;34m[0m[0m
[1;32m      9[0m               [0;34m'Date of Birth T.A.'[0m[0;34m:[0m [0;34m[[0m[0;36m2990[0m[0;34m][0m[0;34m[0m[0;34m[0m[0m

[0;32m~/miniforge3/envs/myenv/lib/python3.9/site-packages/pandas/core/generic.py[0m in [0;36m?[0;34m(self, name)[0m
[1;32m   6200[0m             [0;32mand[0m [0mname[0m [0;32mnot[0m [0;32min[0m [0mself[0m[0;34m.[0m[0m_accessors[0m[0;34m[0m[0;34m[0m[0m
[1;32m   6201[0m             [0;32mand[0m [0mself[0m[0;34m.[0m[0m_info_axis[0m[0;34m.[0m[0m_can_hold_identifiers_and_holds_name[0m[0;34m([0m[0mname[0m[0;34m)[0m[0;34m[0m[0;34m[0m[0m
[1;32m   6202[0m         ):
[1;32m   6203[0m             [0;32mreturn[0m [0mself[0m[0;34m[[0m[0mname[0m[0;34m][0m[0;34m[0m[0;34m[0m[0m
[0;32m-> 6204[0;31m         [0;32mreturn[0m [0mobject[0m[0;34m.[0m[0m__getattribute__[0m[0;34m([0m[0mself[0m[0;34m,[0m [0mname[0m[0;34m)[0m[0;34m[0m[0;34m[0m[0m
[0m
[0;31mAttributeError[0m: 'DataFrame' object has no attribute 'append'
AttributeError: 'DataFrame' object has no attribute 'append'

